Workbook
Name AccountType: Masters!$J$4:$J$6
Name ApplicationType: Masters!$G$4:$G$4
Name BooleanFlag: Masters!$S$4:$S$5
Name ConstitutionType: Masters!$AH$4:$AH$23
Name CountryCode: Masters!$BC$4:$BC$252
Name DocumentMaster: Masters!$AT$4:$AT$36
Name FatherSpouseFlag: Masters!$P$4:$P$5
Name Gender: Masters!$A$4:$A$6
Name IdentityCode: Masters!$AN$4:$AN$26
Name IdentityVerificationFlag: Masters!$AE$4:$AE$4
Name KYCDocType: Masters!$V$4:$V$9
Name KYCDocTypeLE: Masters!$Y$4:$Y$5
Name ProofOfAddress: Masters!$AQ$4:$AQ$20
Name RelatedPersonAddDel: Masters!$AB$4:$AB$5
Name RelatedPersonType: Masters!$AK$4:$AK$18
Name ResidentialStatus: Masters!$M$4:$M$7
Name StateMaster: Masters!$AZ$4:$AZ$45
Name TypeOfImpairment: Masters!$AW$4:$AW$23
Name YN: Masters!$D$4:$D$5

Sheet Instructions
A1: CKYC Bulk Upload Utility – New Individual Customer(s)
A4: WHAT THIS WORKBOOK DOES
A5: This workbook is a data-entry utility for building a CKYC-format Bulk Upload file (per Bulk File Structure V1.3) for NEW customers.
A6: It is pre-configured for INDIVIDUAL applicants, Application Type = 01 (New). Fields that are 'Not applicable' for a new upload
A7: (update flags, download-response counters, deceased fields, CKYC reference no.) are locked / auto-blanked for you.
A9: SHEETS IN THIS WORKBOOK
A10: 1. Header (10) - one row, the file-level header record for the whole batch.
A11: 2. Applicant (20) - one row PER CUSTOMER. This is the main data-entry sheet.
A12: 3. Identity (30) - one row per ID proof for a customer (PAN, Aadhaar, etc). Link via 'Applicant Line No'.
A13: 4. Related Person (40) - one row per related person (guardian/nominee/director etc). Link via 'Applicant Line No'.
A14: 5. Images (70) - one row per scanned image filed for a customer. Link via 'Applicant Line No'.
A15: 6. Masters - reference lists (also feed the dropdowns). Do not edit.
... A40: entering real data.

Sheet Header (10)
A1: Detail Record 10 - File Header (fill once per batch)
A3: Sr.no | B3: Field (per Bulk File Structure V1.3) | C3: Value | D3: Format / Size | E3: Remarks
A4: 1 | B4: Record Type | C4: 10 | D4: Number (2) [M] | E4: '10' (Header)
A5: 2 | B5: Batch Number | C5: 00001 | D5: Number (5) [M]
A6: 3 | B6: FI Code | C6: IN7603 | D6: Varchar (7) [M] | E6: Special Characters not allowed
A7: 4 | B7: Region Code | C7: REGION13 | D7: Varchar (10) [M] | E7: Special Characters not allowed
A8: 5 | B8: Total No of Detail Records | C8: =COUNT('Applicant (20)'!A6:A100000) -> 1 | D8: Number (7) [M]
A9: 6 | B9: Create Date | C9: 46263 | D9: Date (10) [M] | E9: DD-MM-YYYY
A10: 7 | B10: Version Number | C10: V1.3 | D10: Varchar (4) [M] | E10: V1.3
A11: 8 | B11: CUST Type | C11: 01 | D11: Number (2) [M] | E11: 01- Individual 02 - Legal Entity
A12: 9 | B12: Filler2 | D12: Character (50) [O]
A13: 10 | B13: Filler3 | D13: Character (50) [O]
A14: 11 | B14: Filler4 | D14: Character (50) [O]
A16: Pipe line: | B16: =_xlfn.TEXTJOIN("|",FALSE(),C4,C5,C6,C7,C8,TEXT(C9,"DD-MM-YYYY"),C10,C11,C12,C13,C14) -> 10|00001|IN7603|REGION13|1|29-08-2026|V1.3|01|||
A17: Upload file name to use: | B17: =IF(C6="","",C6&"_"&C7&"_"&TEXT(C9,"DDMMYYYY")&"_"&C10&"_<YOUR USERID>_U"&TEXT(C5,"00000")&".txt") -> IN7603_REGION13_29082026_V1.3_<YOUR USERID>_U00001.txt
A18: (replace <YOUR USERID> with your actual CKYC portal user ID before saving)

Sheet Applicant (20)
A1: Detail Record 20 - Applicant / New Individual Customer (one row per customer)
A2: Key | B2: System Use | C2: System Use | D2: System Use | E2: System Use | F2: Updation Module | G2: Updation Module | H2: Updation Module | I2: Updation Module | J2: Updation Module | K2: Updation Module | L2: Updation Module | M2: Updation Module | N2: Download response | O2: Updation Module | P2: Personal/Entity Details | Q2: Personal/Entity Details | R2: Download response | S2: Personal/Entity Details | T2: System Use | U2: Personal/Entity Details | V2: Personal/Entity Details | W2: Personal/Entity Details | X2: Personal/Entity Details | Y2: Applicant Name Update | Z2: Personal/Entity Details | AA2: Personal/Entity Details | AB2: Personal/Entity Details | AC2: Personal/Entity Details | AD2: Personal/Entity Details | AE2: Personal/Entity Details | AF2: Personal/Entity Details | AG2: Personal/Entity Details | AH2: Personal/Entity Details | AI2: Personal/Entity Details | AJ2: Personal/Entity Details | AK2: Personal/Entity Details | AL2: Personal/Entity Details | AM2: Personal/Entity Details | AN2: Personal/Entity Details | AO2: Personal/Entity Details | AP2: Personal/Entity Details | AQ2: Blank field | AR2: Blank field | AS2: Blank field | AT2: Personal/Entity Details | AU2: Personal/Entity Details | AV2: Personal/Entity Details | AW2: Personal/Entity Details | AX2: Blank field | AY2: Other Details/Deceased information | AZ2: Personal/Entity Details | BA2: Personal/Entity Details | BB2: Personal/Entity Details | BC2: Personal/Entity Details | BD2: Personal/Entity Details | BE2: Personal/Entity Details | BF2: Personal/Entity Details | BG2: Personal/Entity Details | BH2: Blank field | BI2: Blank field | BJ2: Address Details | BK2: Address Details | BL2: Address Details | BM2: Address Details | BN2: Address Details | BO2: Address Details | BP2: Address Details | BQ2: Address Details | BR2: Address Details | BS2: Address Details | BT2: Address Details | BU2: Blank field | BV2: Address Details | BW2: Address Details | BX2: Address Details | BY2: Address Details | BZ2: Address Details | CA2: Address Details | CB2: Address Details | CC2: Address Details | CD2: Address Details | CE2: Blank field | CF2: Blank field | CG2: Blank field | CH2: Blank field | CI2: Blank field | CJ2: Blank field | CK2: Blank field | CL2: Blank field | CM2: Blank field | CN2: Blank field | CO2: Contact Details | CP2: Contact Details | CQ2: Contact Details | CR2: Contact Details | CS2: Contact Details | CT2: Contact Details | CU2: Contact Details | CV2: Contact Details | CW2: Contact Details | CX2: Other Details/Deceased information | CY2: KYC Verification | CZ2: KYC Verification | DA2: KYC Verification | DB2: KYC Verification | DC2: KYC Verification | DD2: KYC Verification | DE2: KYC Verification | DF2: KYC Verification | DG2: KYC Verification | DH2: KYC Verification | DI2: Identity Details | DJ2: Related Person Details | DK2: KYC Verification | DL2: Other Details/Deceased information | DM2: Image Details | DN2: System Use | DO2: Contact Details | DP2: Contact Details | DQ2: Contact Details | DR2: System Use
A3: Line No | B3: 1. Record Type | C3: 2. Line Number | D3: 3. Application Type | E3: 4. Branch Code | F3: 5. Applicant/Entity Name Update Flag | G3: 6. Personal/Entity Details Update Flag | H3: 7. Address Details Update Flag | I3: 8. Contact Details Update Flag | J3: 9. Other Details/Deceased information | K3: 10. KYC Verification Update Flag | L3: 11. Identity Details Update Flag | M3: 12. Related Person Details Update Flag | N3: 13. Count of download of the CKYC record in the last 5 years by various reporting entities | O3: 14. Image Details Update Flag | P3: 15. Constitution Type | Q3: 16. Constitution Type others | R3: 17. Count of update of the CKYC record in the last 5 years by various reporting entities | S3: 18. Account type | T3: 19. CKYC no / FI reference No | U3: 20. Applicant Name Prefix | V3: 21. Applicant First Name | W3: 22. Applicant Middle Name | X3: 23. Applicant Last Name | Y3: 24. Name of the Entity | Z3: 25. Applicant Maiden Name Prefix | AA3: 26. Applicant Maiden First Name | AB3: 27. Applicant Maiden Middle Name | AC3: 28. Applicant Maiden Last Name | AD3: 29. Applicant Maiden Full Name | AE3: 30. Flag indicating Father or Spouse Name | AF3: 31. Applicant Father/Spouse Name Prefix | AG3: 32. Father / Spouse First Name | AH3: 33. Father / Spouse Middle Name | AI3: 34. Father / Spouse Last Name | AJ3: 35. Father / Spouse Full Name | AK3: 36. Applicant Mother Name Prefix | AL3: 37. Mother's First Name | AM3: 38. Mother's Middle Name | AN3: 39. Mother's Last Name | AO3: 40. Mother's Full Name | AP3: 41. Gender | AQ3: 42. Marital status | AR3: 43. Nationality | AS3: 44. Occupation Type | AT3: 45. Date of Birth/ Date of Incorporation | AU3: 46. Place of Incorporation | AV3: 47. Date of Commencement of business | AW3: 48. Country of Incorporation | AX3: 49. Country of residence as per Tax Laws | AY3: 50. Deceased date | AZ3: 51. TIN/GST Registration number | BA3: 52. TIN Issuing Country | BB3: 53. PAN or form 60 | BC3: 54. Residential Status | BD3: 55. Differently Abled status Flag | BE3: 56. Type of impairment | BF3: 57. Percentage of impairment | BG3: 58. UDID number | BH3: 59. City/Place of Birth | BI3: 60. Current/ Permanent/ Overseas Address Type | BJ3: 61. Individual Record: Proof of Identity and Address Line 1 Legal Entity: Registered Address Line 1 | BK3: 62. Individual Record: Proof of Identity and Address Line 2 Legal Entity: Registered Address Line 2 | BL3: 63. Individual Record: Proof of Identity and Address Line 3 Legal Entity: Registered Address Line 3 | BM3: 64. Individual Record: Proof of Identity and Address - City / Town / Village Legal Entity: Registered Address City/Town/Village | BN3: 65. Individual Record: Proof of Identity and Address - District Legal Entity: Registered Address District | BO3: 66. Individual Record: Proof of Identity and Address - State/ U.T Legal Entity: Registered Address State/UT | BP3: 67. Individual Record: Proof of Identity and Address - Country Legal Entity: Registered Address Country | BQ3: 68. Individual Record: Proof of Identity and Address - PIN Code Legal Entity: Registered Address Pincode | BR3: 69. Individual Record: Proof of Address submitted for Proof of Identity and Address Legal Entity: Proof submitted for Registered Address | BS3: 70. Legal Entity: Proof of Address submitted for Registered Address (Others) | BT3: 71. Individual Record: Flag indicating if Proof of Identity and Address is same as current Address Legal Entity: Flag indicating if Registered Address is same as Local Address in India | BU3: 72. Correspondence/ Local Address Type | BV3: 73. Individual Record:Current Address Line 1 Legal Entity: Local Address Line 1 | BW3: 74. Individual Record:Current Address Line 2 Legal Entity: Local Address Line 2 | BX3: 75. Individual Record:Current Address Line 3 Legal Entity: Local Address Line 3 | BY3: 76. Individual Record:Current Address - City / Town / Village Legal Entity: Local Address City/Town/Village | BZ3: 77. Individual Record:Current Address - District Legal Entity: Local Address Ditrict | CA3: 78. Individual Record:Current Address - State Legal Entity: Local Address State | CB3: 79. Individual Record:Current Address - Country Legal Entity: Local Address Country | CC3: 80. Individual Record:Current Address - PIN Code Legal Entity: Local Address Pin code | CD3: 81. Individual Record: Proof of address submitted for Current Address | CE3: 82. Flag indicating if address in jurisdiction where application is resident is same as Current/ Permanent/ Overseas or Correspondence/ Local address details | CF3: 83. Address in Jurisdiction Type | CG3: 84. Address in Jurisdiction Line 1 | CH3: 85. Address in Jurisdiction Line 2 | CI3: 86. Address in Jurisdiction Line 3 | CJ3: 87. Address in Jurisdiction - City / Town / Village | CK3: 88. Address in Jurisdiction - State | CL3: 89. Address in Jurisdiction - Country | CM3: 90. Address in Jurisdiction - ZIP/Post Code | CN3: 91. Proof of Address submitted for Address in Jurisdiction | CO3: 92. Residence Telephone No. (STD Code) | CP3: 93. Residence Telephone No. | CQ3: 94. Office Telephone No. (STD Code) | CR3: 95. Office Telephone No. | CS3: 96. Mobile No. (ISD Code) | CT3: 97. Mobile No. | CU3: 98. Fax No. (STD Code) | CV3: 99. Fax No. | CW3: 100. Email ID | CX3: 101. Remarks, if any | CY3: 102. Date of Declaration | CZ3: 103. Place of Declaration | DA3: 104. KYC Verification Date | DB3: 105. Type of Document Submitted | DC3: 106. KYC Verification Name | DD3: 107. KYC Verification Designation | DE3: 108. KYC Verification Branch | DF3: 109. KYC Verification EMP code | DG3: 110. Organisation Name | DH3: 111. Organisation Code | DI3: 112. Number of Identity Details | DJ3: 113. Number of related people | DK3: 114. Identity Verification Flag | DL3: 115. Deceased Flag | DM3: 116. Number of Images | DN3: 117. Error Code | DO3: 118. Mobile No. 2 (ISD Code) | DP3: 119. Mobile No. 2 | DQ3: 120. Email ID 2 | DR3: 121. CKYC Reference ID | DS3: (helper) Pipe line
B4: M | C4: M | D4: M | E4: M | F4: M/O | G4: M/O | H4: M/O | I4: M/O | J4: M/O | K4: M/O | L4: M/O | M4: M/O | N4: M | O4: M/O | P4: M | Q4: M/O | R4: M | S4: M | T4: M | U4: M | V4: M | W4: O | X4: O | Y4: M/O | Z4: O | AA4: O | AB4: O | AC4: O | AD4: NA | AE4: M/O | AF4: M/O | AG4: M/O | AH4: M/O | AI4: M/O | AJ4: NA | AK4: M/O | AL4: M/O | AM4: M/O | AN4: M/O | AO4: NA | AP4: M | AT4: M | AU4: M | AV4: M/O | AW4: M | AY4: M/O | AZ4: O | BA4: M/O | BB4: M | BC4: M | BD4: M | BE4: M/O | BF4: M/O | BG4: M/O | BJ4: M | BK4: O | BL4: O | BM4: M | BN4: M/O | BO4: M | BP4: M | BQ4: M/O | BR4: M | BS4: M/O | BT4: M | BU4: M | BV4: M/O | BW4: O | BX4: O | BY4: M | BZ4: M/O | CB4: M | CC4: M/O | CD4: M/O | CO4: M/O | CP4: M/O | CQ4: M/O | CR4: M/O | CS4: M/O | CT4: M/O | CU4: M/O | CV4: M/O | CW4: O | CX4: O | CY4: M | CZ4: M | DA4: M | DB4: M | DC4: M | DD4: M | DE4: M | DF4: M | DG4: M | DH4: M | DI4: M | DJ4: M | DK4: M | DL4: M/O | DM4: M | DN4: O | DO4: M/O | DP4: M/O | DR4: M
B5: Number 2 | C5: Number 5 | D5: Number 2 | E5: Number 10 | F5: Number 2 | G5: Number 2 | H5: Number 2 | I5: Number 2 | J5: Number 2 | K5: Number 2 | L5: Number 2 | M5: Number 2 | N5: Number 20 | O5: Number 2 | P5: Varchar 2 | Q5: Varchar 20 | R5: Number 20 | S5: Number 2 | T5: Varchar 14 | U5: Character 5 | V5: Character 50 | W5: Character 50 | X5: Character 50 | Y5: Character 150 | Z5: Character 5 | AA5: Character 50 | AB5: Character 50 | AC5: Character 50 | AD5: Character 150 | AE5: Number 2 | AF5: Character 5 | AG5: Character 50 | AH5: Character 50 | AI5: Character 50 | AJ5: Character 150 | AK5: Character 5 | AL5: Character 50 | AM5: Character 50 | AN5: Character 50 | AO5: Character 150 | AP5: Character 1 | AT5: Date 10 | AU5: Character 50 | AV5: Date 10 | AW5: Character 2 | AY5: Date 10 | AZ5: Varchar 20 | BA5: Character 2 | BB5: Varchar 10 | BC5: Number 2 | BD5: Boolean 1 | BE5: Number | BF5: Number 3 | BG5: Varchar 18 | BJ5: Character 55 | BK5: Character 55 | BL5: Character 55 | BM5: Varchar 50 | BN5: Character 50 | BO5: Character 2 | BP5: Character 2 | BQ5: Character 10 | BR5: Character 3 | BS5: Character 75 | BT5: Character 1 | BU5: Number 2 | BV5: Varchar 55 | BW5: Varchar 55 | BX5: Varchar 55 | BY5: Varchar 50 | BZ5: Character 50 | CA5: Character 2 | CB5: Character 3 | CC5: Character 10 | CD5: Character 2 | CO5: Number 4 | CP5: Number 10 | CQ5: Number 4 | CR5: Number 10 | CS5: Number 3 | CT5: Number 20 | CU5: Number 4 | CV5: Number 10 | CW5: Varchar 100 | CX5: Character 300 | CY5: Date 10 | CZ5: Character 50 | DA5: Date 10 | DB5: Number 2 | DC5: Character 150 | DD5: Character 50 | DE5: Character 50 | DF5: Character 50 | DG5: Character 150 | DH5: Character 7 | DI5: Number 2 | DJ5: Number 3 | DK5: Number 2 | DL5: Number 1 | DM5: Number 2 | DN5: Varchar 870 | DO5: Number 3 | DP5: Number 20 | DR5: Varchar 14
A6: =IF(E6="","",ROW()-5) -> 1 | B6: 20 | C6: 1 | D6: 01 | E6: BRANCH13 | N6: 11 | P6: 01 | R6: 1 | S6: 01 | T6: 40037412143945 | U6: FIO | V6: lego | W6: ihfs | X6: khda | AE6: 01 | AF6: ikuhe | AG6: ukf | AH6: keu | AI6: kd | AP6: M | AT6: 15-07-1982 | BB6: FORM60 | BC6: 01 | BD6: 1 | BE6: 1 | BF6: 34 | BG6: AB1234567891234567 | BJ6: uiahuh | BK6: usfwf | BL6: afea | BM6: Coimbatore | BN6: Coimbatore | BO6: TN | BP6: IN | BQ6: 641004 | BR6: 02 | BT6: Y | BV6: uiahfiewufweiuh | BW6: usdahfiefwf | BX6: awefwfea | BY6: Coimbatore | BZ6: Coimbatore | CA6: TN | CB6: IN | CC6: 641004 | CD6: 02 | CT6: 7709047001 | CW6: sameer.dalal@ltimindtree.com | CY6: 01-08-2024 | CZ6: awefweawe | DA6: 01-08-2024 | DB6: 02 | DC6: waefwefwaa | DD6: sadfasd | DE6: fawefawef | DF6: sdfewa | DG6: FI Testing | DH6: IN6488 | DI6: 1 | DJ6: 1 | DM6: 2 | DS6: =IF(A6="","",_xlfn.TEXTJOIN("|",FALSE(),B6:DR6)) -> 20|1|01|BRANCH13|||||||||11||01||1|01|40037412143945|FIO|lego|ihfs|khda|||||||01|ikuhe|ukf|keu|kd|||||||M||||15-07-1982||||||||FORM60|01|1|1|34|AB1234567891234567|||uiahuh|usfwf|afea|Coimbatore|Coimbatore|TN|IN|641004|02||Y||uiahfiewufweiuh|usdahfiefwf|awefwfea|Coimbatore|Coimbatore|TN|IN|641004|02||||||||||||||||7709047001|||sameer.dalal@ltimindtree.com||01-08-2024|awefweawe|01-08-2024|02|waefwefwaa|sadfasd|fawefawef|sdfewa|FI Testing|IN6488|1|1|||2|||||
A7: =IF(E7="","",ROW()-5) | DS7: =IF(A7="","",_xlfn.TEXTJOIN("|",FALSE(),B7:DR7))
A8: =IF(E8="","",ROW()-5) | DS8: =IF(A8="","",_xlfn.TEXTJOIN("|",FALSE(),B8:DR8))
A9: =IF(E9="","",ROW()-5) | DS9: =IF(A9="","",_xlfn.TEXTJOIN("|",FALSE(),B9:DR9))
A10: =IF(E10="","",ROW()-5) | DS10: =IF(A10="","",_xlfn.TEXTJOIN("|",FALSE(),B10:DR10))
A11: =IF(E11="","",ROW()-5) | DS11: =IF(A11="","",_xlfn.TEXTJOIN("|",FALSE(),B11:DR11))
A12: =IF(E12="","",ROW()-5) | DS12: =IF(A12="","",_xlfn.TEXTJOIN("|",FALSE(),B12:DR12))
A13: =IF(E13="","",ROW()-5) | DS13: =IF(A13="","",_xlfn.TEXTJOIN("|",FALSE(),B13:DR13))
A14: =IF(E14="","",ROW()-5) | DS14: =IF(A14="","",_xlfn.TEXTJOIN("|",FALSE(),B14:DR14))
A15: =IF(E15="","",ROW()-5) | DS15: =IF(A15="","",_xlfn.TEXTJOIN("|",FALSE(),B15:DR15))
A16: =IF(E16="","",ROW()-5) | DS16: =IF(A16="","",_xlfn.TEXTJOIN("|",FALSE(),B16:DR16))
A17: =IF(E17="","",ROW()-5) | DS17: =IF(A17="","",_xlfn.TEXTJOIN("|",FALSE(),B17:DR17))
A18: =IF(E18="","",ROW()-5) | DS18: =IF(A18="","",_xlfn.TEXTJOIN("|",FALSE(),B18:DR18))
... A46: =IF(E46="","",ROW()-5) | DS46: =IF(A46="","",_xlfn.TEXTJOIN("|",FALSE(),B46:DR46))

Sheet Identity (30)
A1: Detail Record 30 - Identity / ID Proof (one row per ID document; repeat Applicant Line No for more than one ID)
A2: System Use | B2: System Use | C2: Identity Details | D2: Identity Details | E2: Identity Details | F2: Blank field | G2: Identity Details | H2: Identity Details
A3: 1. Record Type | B3: 2. Line Number [= Applicant Line No] | C3: 3. Identification type | D3: 4. Identity Number | E3: 5. Other Identity description | F3: 6. Expiry Date | G3: 7. Identity Proof Submitted | H3: 8. Identity Verification status | I3: 9. Filler - 1 | J3: 10. Filler - 2 | K3: 11. Filler - 3 | L3: 12. Filler - 4 | M3: (helper) Occurrence | N3: (helper) Key | O3: (helper) Pipe line
A4: M | B4: M | C4: M | D4: M/O | E4: O | H4: O | I4: O | J4: O | K4: O | L4: O
A5: Number 2 | B5: Number 5 | C5: Varchar 3 | D5: As per Identity Code master As per Identity Code master | E5: Varchar | H5: Yes / No 2 | I5: Character 50 | J5: Character 50 | K5: Character 50 | L5: Character 50
A6: 30 | B6: 1 | C6: A | D6: T134erYSTIN | H6: 02 | M6: =IF(B6="","",COUNTIF($B$6:B6,B6)) -> 1 | N6: =IF(B6="","",B6&"-"&M6) -> 1-1 | O6: =IF(B6="","",_xlfn.TEXTJOIN("|",FALSE(),A6:L6)) -> 30|1|A|T134erYSTIN||||02||||
A7: 30 | M7: =IF(B7="","",COUNTIF($B$6:B7,B7)) | N7: =IF(B7="","",B7&"-"&M7) | O7: =IF(B7="","",_xlfn.TEXTJOIN("|",FALSE(),A7:L7))
A8: 30 | M8: =IF(B8="","",COUNTIF($B$6:B8,B8)) | N8: =IF(B8="","",B8&"-"&M8) | O8: =IF(B8="","",_xlfn.TEXTJOIN("|",FALSE(),A8:L8))
A9: 30 | M9: =IF(B9="","",COUNTIF($B$6:B9,B9)) | N9: =IF(B9="","",B9&"-"&M9) | O9: =IF(B9="","",_xlfn.TEXTJOIN("|",FALSE(),A9:L9))
A10: 30 | M10: =IF(B10="","",COUNTIF($B$6:B10,B10)) | N10: =IF(B10="","",B10&"-"&M10) | O10: =IF(B10="","",_xlfn.TEXTJOIN("|",FALSE(),A10:L10))
A11: 30 | M11: =IF(B11="","",COUNTIF($B$6:B11,B11)) | N11: =IF(B11="","",B11&"-"&M11) | O11: =IF(B11="","",_xlfn.TEXTJOIN("|",FALSE(),A11:L11))
A12: 30 | M12: =IF(B12="","",COUNTIF($B$6:B12,B12)) | N12: =IF(B12="","",B12&"-"&M12) | O12: =IF(B12="","",_xlfn.TEXTJOIN("|",FALSE(),A12:L12))
A13: 30 | M13: =IF(B13="","",COUNTIF($B$6:B13,B13)) | N13: =IF(B13="","",B13&"-"&M13) | O13: =IF(B13="","",_xlfn.TEXTJOIN("|",FALSE(),A13:L13))
A14: 30 | M14: =IF(B14="","",COUNTIF($B$6:B14,B14)) | N14: =IF(B14="","",B14&"-"&M14) | O14: =IF(B14="","",_xlfn.TEXTJOIN("|",FALSE(),A14:L14))
A15: 30 | M15: =IF(B15="","",COUNTIF($B$6:B15,B15)) | N15: =IF(B15="","",B15&"-"&M15) | O15: =IF(B15="","",_xlfn.TEXTJOIN("|",FALSE(),A15:L15))
A16: 30 | M16: =IF(B16="","",COUNTIF($B$6:B16,B16)) | N16: =IF(B16="","",B16&"-"&M16) | O16: =IF(B16="","",_xlfn.TEXTJOIN("|",FALSE(),A16:L16))
A17: 30 | M17: =IF(B17="","",COUNTIF($B$6:B17,B17)) | N17: =IF(B17="","",B17&"-"&M17) | O17: =IF(B17="","",_xlfn.TEXTJOIN("|",FALSE(),A17:L17))
A18: 30 | M18: =IF(B18="","",COUNTIF($B$6:B18,B18)) | N18: =IF(B18="","",B18&"-"&M18) | O18: =IF(B18="","",_xlfn.TEXTJOIN("|",FALSE(),A18:L18))
... A46: 30 | M46: =IF(B46="","",COUNTIF($B$6:B46,B46)) | N46: =IF(B46="","",B46&"-"&M46) | O46: =IF(B46="","",_xlfn.TEXTJOIN("|",FALSE(),A46:L46))

Sheet Related Person (40)
A1: Detail Record 40 - Related Person (guardian / nominee / director etc.) - one row per related person
A2: System Use | B2: System Use | C2: Related Person Details | D2: Updation Module | E2: Related Person Details | F2: Related Person Details | G2: Related Person Details | H2: Related Person Details | I2: Related Person Details | J2: Related Person Details | K2: Related Person Details | L2: Related Person Details | M2: Related Person Details | N2: Related Person Details | O2: Related Person Details | P2: Related Person Details | Q2: Related Person Details | R2: Related Person Details | S2: Related Person Details | T2: Related Person Details | U2: Related Person Details | V2: Related Person Details | W2: Related Person Details | X2: Related Person Details | Y2: Blank field | Z2: Related Person Details | AA2: Related Person Details | AB2: Personal/Entity Details | AC2: Personal/Entity Details | AD2: Personal/Entity Details | AE2: Personal/Entity Details | AF2: Blank field | AG2: Blank field | AH2: Related Person Details | AI2: Related Person Details | AJ2: Related Person Details | AK2: Related Person Details | AL2: Related Person Details | AM2: Related Person Details | AN2: Related Person Details | AO2: Related Person Details | AP2: Related Person Details | AQ2: Related Person Details | AR2: Related Person Details | AS2: Related Person Details | AT2: Related Person Details | AU2: Related Person Details | AV2: Related Person Details | AW2: Related Person Details | AX2: Related Person Details | AY2: Related Person Details | AZ2: Related Person Details | BA2: Related Person Details | BB2: Related Person Details | BC2: Related Person Details | BD2: Related Person Details | BE2: Related Person Details | BF2: Related Person Details | BG2: Related Person Details | BH2: Related Person Details | BI2: Related Person Details | BJ2: Related Person Details | BK2: Related Person Details | BL2: Related Person Details | BM2: Related Person Details | BN2: Related Person Details | BO2: Related Person Details | BP2: Related Person Details | BQ2: Related Person Details | BR2: Related Person Details | BS2: Related Person Details | BT2: Blank field | BU2: Blank field | BV2: Related Person Details | BW2: Related Person Details | BX2: Related Person Details | BY2: Related Person Details | BZ2: Related Person Details | CA2: Related Person Details | CB2: Related Person Details | CC2: Related Person Details | CD2: Related Person Details | CE2: Related Person Details | CF2: Related Person Details | CG2: Related Person Details | CH2: Remarks | CI2: Related Person Details
A3: 1. Record Type | B3: 2. Line Number [= Applicant Line No] | C3: 3. Type of Relationship | D3: 4. Addition / Deletion of Related Person | E3: 5. KYC Number of Related Person | F3: 6. Related Person Name Prefix | G3: 7. Related Person First Name | H3: 8. Related Person Middle Name | I3: 9. Related Person Last Name | J3: 10. Related Person Maiden Name Prefix | K3: 11. Related Person Maiden First Name | L3: 12. Related Person Maiden Middle Name | M3: 13. Related Person Maiden Last Name | N3: 14. Flag indicating Reated person Father or Spouse Name | O3: 15. Related Person Father/Spouse Name Prefix | P3: 16. Related Person Father / Spouse First Name | Q3: 17. Related Person Father / Spouse Middle Name | R3: 18. Reated person Father / Spouse Last Name | S3: 19. Related Person Mother Name Prefix | T3: 20. Related Person Mother's First Name | U3: 21. Related Person Mother's Middle Name | V3: 22. Related Person Mother's Last Name | W3: 23. Date of Birth | X3: 24. Gender | Y3: 25. Maritial Status | Z3: 26. Nationality | AA3: 27. Residential Status | AB3: 28. Differently Abled status Flag | AC3: 29. Type of impairment | AD3: 30. Percentage of impairment | AE3: 31. UDID number | AF3: 32. Country of birth | AG3: 33. City/Place of Birth | AH3: 34. PAN/Form 60 | AI3: 35. Proof of possession of Aadhaar | AJ3: 36. Voter ID Card | AK3: 37. NREGA Job Card | AL3: 38. Passport No | AM3: 39. Documents issued by Government departments of foreign jurisdictions and letter issued by Foreign Embassy or Mission in India API tag: <FOREIGN_NATIONAL_ID> | AN3: 40. Driving Licence No | AO3: 41. National Population register letter | AP3: 42. E-KYC Authentication | AQ3: 43. Offline verification of Aadhaar | AR3: 44. Image name in the folder fo r Photograph | AS3: 45. Image name in the folder fo r Proof submitted for Proof of Identity and Address | AT3: 46. Image name in the folder fo r Proof submitted for Current Address | AU3: 47. Proof of Identity and Address Line 1 | AV3: 48. Proof of Identity and Address Line 2 | AW3: 49. Proof of Identity and Address Line 3 | AX3: 50. Proof of Identity and Address - City / Town / Village | AY3: 51. Proof of Identity and Address - District | AZ3: 52. Proof of Identity and Address - PIN Code | BA3: 53. Proof of Identity and Address - State | BB3: 54. Proof of Identity and Address - Country | BC3: 55. Proof submitted for Proof of Identity and Address | BD3: 56. Flag indicating if Proof of Identity and Address is same as current Address for related person | BE3: 57. Current Address Line 1 | BF3: 58. Current Address Line 2 | BG3: 59. Current Address Line 3 | BH3: 60. Current Address - City / Town / Village | BI3: 61. Current Address - District | BJ3: 62. Current Address - State | BK3: 63. Current Address - Country | BL3: 64. Current Address - PIN Code | BM3: 65. Proof of address submitted for Current Address | BN3: 66. Residence Telephone No. (STD Code) | BO3: 67. Residence Telephone No. | BP3: 68. Office Telephone No. (STD Code) | BQ3: 69. Office Telephone No. | BR3: 70. Mobile No. (ISD Code) | BS3: 71. Mobile No. | BT3: 72. Fax No. (STD Code) | BU3: 73. Fax No. | BV3: 74. Email ID | BW3: 75. Date of Declaration | BX3: 76. Place of Declaration | BY3: 77. KYC Verification Date | BZ3: 78. Type of Document Submitted | CA3: 79. KYC Verification Name | CB3: 80. KYC Verification Designation | CC3: 81. KYC Verification Branch | CD3: 82. KYC Verification EMP code | CE3: 83. Organisation Name | CF3: 84. Organisation Code | CG3: 85. DIN (Director Identification Number) | CH3: 86. Remarks, if any | CI3: 87. Related Person type Others Description | CJ3: 88. Filler 2 | CK3: 89. Filler 3 | CL3: 90. Filler 4 | CM3: (helper) Occurrence | CN3: (helper) Key | CO3: (helper) Pipe line
A4: M | B4: M | C4: M | D4: M | E4: O | F4: M | G4: M | H4: O | I4: O | J4: O | K4: O | L4: O | M4: O | N4: M/O | O4: M/O | P4: M/O | Q4: O | R4: O | S4: M/O | T4: M/O | U4: O | V4: O | W4: M | X4: M | Z4: M | AA4: M | AB4: M | AC4: M/O | AD4: M/O | AE4: M/O | AH4: M | AI4: M/O | AJ4: M/O | AK4: M/O | AL4: M/O | AM4: M/O | AN4: M/O | AO4: M/O | AP4: M/O | AQ4: M/O | AR4: M | AS4: M | AT4: M/O | AU4: M | AV4: O | AW4: O | AX4: M | AY4: M/O | AZ4: M | BA4: M | BB4: M | BC4: M | BD4: M | BE4: M/O | BF4: O | BG4: O | BH4: M | BI4: M/O | BK4: M | BL4: M/O | BM4: M/O | BN4: M/O | BO4: M/O | BP4: M/O | BQ4: M/O | BR4: M/O | BS4: M/O | BV4: O | BW4: M | BX4: M | BY4: M | BZ4: M | CA4: M | CB4: M | CC4: M | CD4: M | CE4: M | CF4: M | CG4: M/O | CH4: O | CI4: M/O
A5: Number 2 | B5: Number 5 | C5: Number 2 | D5: Number 2 | E5: Number 14 | F5: Varchar 5 | G5: Character 50 | H5: Character 50 | I5: Character 50 | J5: Varchar 5 | K5: Character 50 | L5: Character 50 | M5: Character 50 | N5: Number 2 | O5: Varchar 5 | P5: Character 50 | Q5: Character 50 | R5: Character 50 | S5: Varchar 5 | T5: Character 50 | U5: Character 50 | V5: Character 50 | W5: Date 10 | X5: Character 1 | Z5: Character 2 | AA5: Number 2 | AB5: Boolean 1 | AC5: Number | AD5: Number 3 | AE5: Varchar 18 | AH5: Varchar 10 | AI5: Number 2021-04-12 00:00:00 | AJ5: Varchar 20 | AK5: Varchar 20 | AL5: Varchar 20 | AM5: Varchar 20 | AN5: Varchar 20 | AO5: Varchar 20 | AP5: Varchar 4 | AQ5: Varchar 4 | AR5: Varchar 50 | AS5: Varchar 50 | AT5: Varchar 50 | AU5: Varchar 55 | AV5: Varchar 55 | AW5: Varchar 55 | AX5: Varchar 50 | AY5: Character 50 | AZ5: Number 10 | BA5: Character 2 | BB5: Character 2 | BC5: Character 3 | BD5: Character 1 | BE5: Varchar 55 | BF5: Varchar 55 | BG5: Varchar 55 | BH5: Varchar 50 | BI5: Character 50 | BJ5: Character 2 | BK5: Character 3 | BL5: Character 10 | BM5: Character 2 | BN5: Number 4 | BO5: Number 10 | BP5: Number 4 | BQ5: Number 10 | BR5: Number 3 | BS5: Number 20 | BV5: Varchar 100 | BW5: Date 10 | BX5: Character 50 | BY5: Date 10 | BZ5: Character 2 | CA5: Character 150 | CB5: Character 50 | CC5: Character 50 | CD5: Character 50 | CE5: Character 150 | CF5: Character 20 | CG5: Number 8 | CH5: Character 300 | CI5: Character 150
A6: 40 | B6: 1 | C6: 1 | D6: 01 | CM6: =IF(B6="","",COUNTIF($B$6:B6,B6)) -> 1 | CN6: =IF(B6="","",B6&"-"&CM6) -> 1-1 | CO6: =IF(B6="","",_xlfn.TEXTJOIN("|",FALSE(),A6:CL6)) -> 40|1|1|01||||||||||||||||||||||||||||||||||||||||||||||||||||||||||||||||||||||||||||||||||||||
A7: 40 | CM7: =IF(B7="","",COUNTIF($B$6:B7,B7)) | CN7: =IF(B7="","",B7&"-"&CM7) | CO7: =IF(B7="","",_xlfn.TEXTJOIN("|",FALSE(),A7:CL7))
A8: 40 | CM8: =IF(B8="","",COUNTIF($B$6:B8,B8)) | CN8: =IF(B8="","",B8&"-"&CM8) | CO8: =IF(B8="","",_xlfn.TEXTJOIN("|",FALSE(),A8:CL8))
A9: 40 | CM9: =IF(B9="","",COUNTIF($B$6:B9,B9)) | CN9: =IF(B9="","",B9&"-"&CM9) | CO9: =IF(B9="","",_xlfn.TEXTJOIN("|",FALSE(),A9:CL9))
A10: 40 | CM10: =IF(B10="","",COUNTIF($B$6:B10,B10)) | CN10: =IF(B10="","",B10&"-"&CM10) | CO10: =IF(B10="","",_xlfn.TEXTJOIN("|",FALSE(),A10:CL10))
A11: 40 | CM11: =IF(B11="","",COUNTIF($B$6:B11,B11)) | CN11: =IF(B11="","",B11&"-"&CM11) | CO11: =IF(B11="","",_xlfn.TEXTJOIN("|",FALSE(),A11:CL11))
A12: 40 | CM12: =IF(B12="","",COUNTIF($B$6:B12,B12)) | CN12: =IF(B12="","",B12&"-"&CM12) | CO12: =IF(B12="","",_xlfn.TEXTJOIN("|",FALSE(),A12:CL12))
A13: 40 | CM13: =IF(B13="","",COUNTIF($B$6:B13,B13)) | CN13: =IF(B13="","",B13&"-"&CM13) | CO13: =IF(B13="","",_xlfn.TEXTJOIN("|",FALSE(),A13:CL13))
A14: 40 | CM14: =IF(B14="","",COUNTIF($B$6:B14,B14)) | CN14: =IF(B14="","",B14&"-"&CM14) | CO14: =IF(B14="","",_xlfn.TEXTJOIN("|",FALSE(),A14:CL14))
A15: 40 | CM15: =IF(B15="","",COUNTIF($B$6:B15,B15)) | CN15: =IF(B15="","",B15&"-"&CM15) | CO15: =IF(B15="","",_xlfn.TEXTJOIN("|",FALSE(),A15:CL15))
A16: 40 | CM16: =IF(B16="","",COUNTIF($B$6:B16,B16)) | CN16: =IF(B16="","",B16&"-"&CM16) | CO16: =IF(B16="","",_xlfn.TEXTJOIN("|",FALSE(),A16:CL16))
A17: 40 | CM17: =IF(B17="","",COUNTIF($B$6:B17,B17)) | CN17: =IF(B17="","",B17&"-"&CM17) | CO17: =IF(B17="","",_xlfn.TEXTJOIN("|",FALSE(),A17:CL17))
A18: 40 | CM18: =IF(B18="","",COUNTIF($B$6:B18,B18)) | CN18: =IF(B18="","",B18&"-"&CM18) | CO18: =IF(B18="","",_xlfn.TEXTJOIN("|",FALSE(),A18:CL18))
... A26: 40 | CM26: =IF(B26="","",COUNTIF($B$6:B26,B26)) | CN26: =IF(B26="","",B26&"-"&CM26) | CO26: =IF(B26="","",_xlfn.TEXTJOIN("|",FALSE(),A26:CL26))

Sheet Images (70)
A1: Detail Record 70 - Scanned Image Reference (one row per image; repeat Applicant Line No for more than one image)
A2: System Use | B2: System Use | C2: Image Details | D2: Image Details | E2: blank field | F2: blank field | G2: Image Details | H2: Image Details | I2: Image Details
A3: 1. Record Type | B3: 2. Line Number [= Applicant Line No] | C3: 3. Image Name in Folder | D3: 4. Image Type | E3: 5. Flag for Global or Local Image | F3: 6. Branch Code | G3: 7. Filler1 | H3: 8. Filler2 | I3: 9. Filler3 | J3: (helper) Occurrence | K3: (helper) Key | L3: (helper) Pipe line
A4: M | B4: M | C4: M | D4: M | G4: O | H4: O | I4: O
A5: Number 2 | B5: Number 7 | C5: Varchar 50 | D5: Number 2 | G5: Character 50 | H5: Character 50 | I5: Character 50
A6: 70 | B6: 1 | C6: 40037412143945_02_08082025142841.TIF | D6: 02 | J6: =IF(B6="","",COUNTIF($B$6:B6,B6)) -> 1 | K6: =IF(B6="","",B6&"-"&J6) -> 1-1 | L6: =IF(B6="","",_xlfn.TEXTJOIN("|",FALSE(),A6:I6)) -> 70|1|40037412143945_02_08082025142841.TIF|02|||||
A7: 70 | J7: =IF(B7="","",COUNTIF($B$6:B7,B7)) | K7: =IF(B7="","",B7&"-"&J7) | L7: =IF(B7="","",_xlfn.TEXTJOIN("|",FALSE(),A7:I7))
A8: 70 | J8: =IF(B8="","",COUNTIF($B$6:B8,B8)) | K8: =IF(B8="","",B8&"-"&J8) | L8: =IF(B8="","",_xlfn.TEXTJOIN("|",FALSE(),A8:I8))
A9: 70 | J9: =IF(B9="","",COUNTIF($B$6:B9,B9)) | K9: =IF(B9="","",B9&"-"&J9) | L9: =IF(B9="","",_xlfn.TEXTJOIN("|",FALSE(),A9:I9))
A10: 70 | J10: =IF(B10="","",COUNTIF($B$6:B10,B10)) | K10: =IF(B10="","",B10&"-"&J10) | L10: =IF(B10="","",_xlfn.TEXTJOIN("|",FALSE(),A10:I10))
A11: 70 | J11: =IF(B11="","",COUNTIF($B$6:B11,B11)) | K11: =IF(B11="","",B11&"-"&J11) | L11: =IF(B11="","",_xlfn.TEXTJOIN("|",FALSE(),A11:I11))
A12: 70 | J12: =IF(B12="","",COUNTIF($B$6:B12,B12)) | K12: =IF(B12="","",B12&"-"&J12) | L12: =IF(B12="","",_xlfn.TEXTJOIN("|",FALSE(),A12:I12))
A13: 70 | J13: =IF(B13="","",COUNTIF($B$6:B13,B13)) | K13: =IF(B13="","",B13&"-"&J13) | L13: =IF(B13="","",_xlfn.TEXTJOIN("|",FALSE(),A13:I13))
A14: 70 | J14: =IF(B14="","",COUNTIF($B$6:B14,B14)) | K14: =IF(B14="","",B14&"-"&J14) | L14: =IF(B14="","",_xlfn.TEXTJOIN("|",FALSE(),A14:I14))
A15: 70 | J15: =IF(B15="","",COUNTIF($B$6:B15,B15)) | K15: =IF(B15="","",B15&"-"&J15) | L15: =IF(B15="","",_xlfn.TEXTJOIN("|",FALSE(),A15:I15))
A16: 70 | J16: =IF(B16="","",COUNTIF($B$6:B16,B16)) | K16: =IF(B16="","",B16&"-"&J16) | L16: =IF(B16="","",_xlfn.TEXTJOIN("|",FALSE(),A16:I16))
A17: 70 | J17: =IF(B17="","",COUNTIF($B$6:B17,B17)) | K17: =IF(B17="","",B17&"-"&J17) | L17: =IF(B17="","",_xlfn.TEXTJOIN("|",FALSE(),A17:I17))
A18: 70 | J18: =IF(B18="","",COUNTIF($B$6:B18,B18)) | K18: =IF(B18="","",B18&"-"&J18) | L18: =IF(B18="","",_xlfn.TEXTJOIN("|",FALSE(),A18:I18))
... A66: 70 | J66: =IF(B66="","",COUNTIF($B$6:B66,B66)) | K66: =IF(B66="","",B66&"-"&J66) | L66: =IF(B66="","",_xlfn.TEXTJOIN("|",FALSE(),A66:I66))

Sheet Build Text File
A1: Final Output – copy Column B (top to bottom) into Notepad and save as .txt
A3: Record | B3: Pipe-delimited line (this is what goes into the .txt file)
A4: Header (10) | B4: ='Header (10)'!B16 -> 10|00001|IN7603|REGION13|1|29-08-2026|V1.3|01|||
A5: Applicant #1 - 20 | B5: ='Applicant (20)'!DS6 -> 20|1|01|BRANCH13|||||||||11||01||1|01|40037412143945|FIO|lego|ihfs|khda|||||||01|ikuhe|ukf|keu|kd|||||||M||||15-07-1982||||||||FORM60|01|1|1|34|AB1234567891234567|||uiahuh|usfwf|afea|Coimbatore|Coimbatore|TN|IN|641004|02||Y||uiahfiewufweiuh|usdahfiefwf|awefwfea|Coimbatore|Coimbatore|TN|IN|641004|02||||||||||||||||7709047001|||sameer.dalal@ltimindtree.com||01-08-2024|awefweawe|01-08-2024|02|waefwefwaa|sadfasd|fawefawef|sdfewa|FI Testing|IN6488|1|1|||2|||||
A6: Identity 30 (#1) | B6: =IFERROR(INDEX('Identity (30)'!$O$6:$O$46,MATCH('Applicant (20)'!$A6&"-"&1,'Identity (30)'!$N$6:$N$46,0)),"") -> 30|1|A|T134erYSTIN||||02||||
A7: Identity 30 (#2) | B7: =IFERROR(INDEX('Identity (30)'!$O$6:$O$46,MATCH('Applicant (20)'!$A6&"-"&2,'Identity (30)'!$N$6:$N$46,0)),"")
A8: Identity 30 (#3) | B8: =IFERROR(INDEX('Identity (30)'!$O$6:$O$46,MATCH('Applicant (20)'!$A6&"-"&3,'Identity (30)'!$N$6:$N$46,0)),"")
A9: Identity 30 (#4) | B9: =IFERROR(INDEX('Identity (30)'!$O$6:$O$46,MATCH('Applicant (20)'!$A6&"-"&4,'Identity (30)'!$N$6:$N$46,0)),"")
A10: Related Person 40 (#1) | B10: =IFERROR(INDEX('Related Person (40)'!$CO$6:$CO$26,MATCH('Applicant (20)'!$A6&"-"&1,'Related Person (40)'!$CN$6:$CN$26,0)),"") -> 40|1|1|01||||||||||||||||||||||||||||||||||||||||||||||||||||||||||||||||||||||||||||||||||||||
A11: Related Person 40 (#2) | B11: =IFERROR(INDEX('Related Person (40)'!$CO$6:$CO$26,MATCH('Applicant (20)'!$A6&"-"&2,'Related Person (40)'!$CN$6:$CN$26,0)),"")
A12: Related Person 40 (#3) | B12: =IFERROR(INDEX('Related Person (40)'!$CO$6:$CO$26,MATCH('Applicant (20)'!$A6&"-"&3,'Related Person (40)'!$CN$6:$CN$26,0)),"")
A13: Image 70 (#1) | B13: =IFERROR(INDEX('Images (70)'!$L$6:$L$66,MATCH('Applicant (20)'!$A6&"-"&1,'Images (70)'!$K$6:$K$66,0)),"") -> 70|1|40037412143945_02_08082025142841.TIF|02|||||
A14: Image 70 (#2) | B14: =IFERROR(INDEX('Images (70)'!$L$6:$L$66,MATCH('Applicant (20)'!$A6&"-"&2,'Images (70)'!$K$6:$K$66,0)),"")
A15: Image 70 (#3) | B15: =IFERROR(INDEX('Images (70)'!$L$6:$L$66,MATCH('Applicant (20)'!$A6&"-"&3,'Images (70)'!$K$6:$K$66,0)),"")
A16: Image 70 (#4) | B16: =IFERROR(INDEX('Images (70)'!$L$6:$L$66,MATCH('Applicant (20)'!$A6&"-"&4,'Images (70)'!$K$6:$K$66,0)),"")
A17: Image 70 (#5) | B17: =IFERROR(INDEX('Images (70)'!$L$6:$L$66,MATCH('Applicant (20)'!$A6&"-"&5,'Images (70)'!$K$6:$K$66,0)),"")
A18: Image 70 (#6) | B18: =IFERROR(INDEX('Images (70)'!$L$6:$L$66,MATCH('Applicant (20)'!$A6&"-"&6,'Images (70)'!$K$6:$K$66,0)),"")
A19: Applicant #2 - 20 | B19: ='Applicant (20)'!DS7
A20: Identity 30 (#1) | B20: =IFERROR(INDEX('Identity (30)'!$O$6:$O$46,MATCH('Applicant (20)'!$A7&"-"&1,'Identity (30)'!$N$6:$N$46,0)),"")
A21: Identity 30 (#2) | B21: =IFERROR(INDEX('Identity (30)'!$O$6:$O$46,MATCH('Applicant (20)'!$A7&"-"&2,'Identity (30)'!$N$6:$N$46,0)),"")
A22: Identity 30 (#3) | B22: =IFERROR(INDEX('Identity (30)'!$O$6:$O$46,MATCH('Applicant (20)'!$A7&"-"&3,'Identity (30)'!$N$6:$N$46,0)),"")
A23: Identity 30 (#4) | B23: =IFERROR(INDEX('Identity (30)'!$O$6:$O$46,MATCH('Applicant (20)'!$A7&"-"&4,'Identity (30)'!$N$6:$N$46,0)),"")
A24: Related Person 40 (#1) | B24: =IFERROR(INDEX('Related Person (40)'!$CO$6:$CO$26,MATCH('Applicant (20)'!$A7&"-"&1,'Related Person (40)'!$CN$6:$CN$26,0)),"")
A25: Related Person 40 (#2) | B25: =IFERROR(INDEX('Related Person (40)'!$CO$6:$CO$26,MATCH('Applicant (20)'!$A7&"-"&2,'Related Person (40)'!$CN$6:$CN$26,0)),"")
A26: Related Person 40 (#3) | B26: =IFERROR(INDEX('Related Person (40)'!$CO$6:$CO$26,MATCH('Applicant (20)'!$A7&"-"&3,'Related Person (40)'!$CN$6:$CN$26,0)),"")
A27: Image 70 (#1) | B27: =IFERROR(INDEX('Images (70)'!$L$6:$L$66,MATCH('Applicant (20)'!$A7&"-"&1,'Images (70)'!$K$6:$K$66,0)),"")
A28: Image 70 (#2) | B28: =IFERROR(INDEX('Images (70)'!$L$6:$L$66,MATCH('Applicant (20)'!$A7&"-"&2,'Images (70)'!$K$6:$K$66,0)),"")
A29: Image 70 (#3) | B29: =IFERROR(INDEX('Images (70)'!$L$6:$L$66,MATCH('Applicant (20)'!$A7&"-"&3,'Images (70)'!$K$6:$K$66,0)),"")
A30: Image 70 (#4) | B30: =IFERROR(INDEX('Images (70)'!$L$6:$L$66,MATCH('Applicant (20)'!$A7&"-"&4,'Images (70)'!$K$6:$K$66,0)),"")
A31: Image 70 (#5) | B31: =IFERROR(INDEX('Images (70)'!$L$6:$L$66,MATCH('Applicant (20)'!$A7&"-"&5,'Images (70)'!$K$6:$K$66,0)),"")
A32: Image 70 (#6) | B32: =IFERROR(INDEX('Images (70)'!$L$6:$L$66,MATCH('Applicant (20)'!$A7&"-"&6,'Images (70)'!$K$6:$K$66,0)),"")
A33: Applicant #3 - 20 | B33: ='Applicant (20)'!DS8
A34: Identity 30 (#1) | B34: =IFERROR(INDEX('Identity (30)'!$O$6:$O$46,MATCH('Applicant (20)'!$A8&"-"&1,'Identity (30)'!$N$6:$N$46,0)),"")
A35: Identity 30 (#2) | B35: =IFERROR(INDEX('Identity (30)'!$O$6:$O$46,MATCH('Applicant (20)'!$A8&"-"&2,'Identity (30)'!$N$6:$N$46,0)),"")
A36: Identity 30 (#3) | B36: =IFERROR(INDEX('Identity (30)'!$O$6:$O$46,MATCH('Applicant (20)'!$A8&"-"&3,'Identity (30)'!$N$6:$N$46,0)),"")
A37: Identity 30 (#4) | B37: =IFERROR(INDEX('Identity (30)'!$O$6:$O$46,MATCH('Applicant (20)'!$A8&"-"&4,'Identity (30)'!$N$6:$N$46,0)),"")
A38: Related Person 40 (#1) | B38: =IFERROR(INDEX('Related Person (40)'!$CO$6:$CO$26,MATCH('Applicant (20)'!$A8&"-"&1,'Related Person (40)'!$CN$6:$CN$26,0)),"")
A39: Related Person 40 (#2) | B39: =IFERROR(INDEX('Related Person (40)'!$CO$6:$CO$26,MATCH('Applicant (20)'!$A8&"-"&2,'Related Person (40)'!$CN$6:$CN$26,0)),"")
A40: Related Person 40 (#3) | B40: =IFERROR(INDEX('Related Person (40)'!$CO$6:$CO$26,MATCH('Applicant (20)'!$A8&"-"&3,'Related Person (40)'!$CN$6:$CN$26,0)),"")
A41: Image 70 (#1) | B41: =IFERROR(INDEX('Images (70)'!$L$6:$L$66,MATCH('Applicant (20)'!$A8&"-"&1,'Images (70)'!$K$6:$K$66,0)),"")
...

Sheet Masters
A1: Reference Master Lists (do not edit - feeds the drop-downs)
A2: Gender | D2: YN | G2: ApplicationType | J2: AccountType | M2: ResidentialStatus | P2: FatherSpouseFlag | S2: BooleanFlag | V2: KYCDocType | Y2: KYCDocTypeLE | AB2: RelatedPersonAddDel | AE2: IdentityVerificationFlag | AH2: ConstitutionType | AK2: RelatedPersonType | AN2: IdentityCode | AQ2: ProofOfAddress | AT2: DocumentMaster | AW2: TypeOfImpairment | AZ2: StateMaster | BC2: CountryCode
A3: Code | B3: Description | D3: Code | E3: Description | G3: Code | H3: Description | J3: Code | K3: Description | M3: Code | N3: Description | P3: Code | Q3: Description | S3: Code | T3: Description | V3: Code | W3: Description | Y3: Code | Z3: Description | AB3: Code | AC3: Description | AE3: Code | AF3: Description | AH3: Code | AI3: Description | AK3: Code | AL3: Description | AN3: Code | AO3: Description | AQ3: Code | AR3: Description | AT3: Code | AU3: Description | AW3: Code | AX3: Description | AZ3: Code | BA3: Description | BC3: Code | BD3: Description
A4: M | B4: Male | D4: Y | E4: Yes | G4: 01 | H4: New | J4: 01 | K4: Normal | M4: 01 | N4: Resident Individual | P4: 01 | Q4: Father Name | S4: 0 | T4: False | V4: 01 | W4: Certified Copies | Y4: 01 | Z4: Certified Copies | AB4: 01 | AC4: Addition of Related Person | AE4: 01 | AF4: Done | AH4: 1 | AI4: Individual | AK4: 1 | AL4: Guardian of minor | AN4: A | AO4: Passport | AQ4: 1 | AR4: Proof of Possession of Aadhaar | AT4: 02 | AU4: Photograph | AW4: 1 | AX4: Blindness | AZ4: AN | BA4: ANDAMAN AND NICOBAR ISLANDS | BC4: AF | BD4: Afghanistan
A5: F | B5: Female | D5: N | E5: No | J5: 04 | K5: OTP Based E-KYC | M5: 02 | N5: Non Resident Indian | P5: 02 | Q5: Spouse Name | S5: 1 | T5: True | V5: 02 | W5: E-KYC data received from UIDAI | Y5: 02 | Z5: Equivalent e-document | AB5: 02 | AC5: Deletion of Related Person | AH5: A | AI5: Sole Proprietorship | AK5: 2 | AL5: Assignee | AN5: B | AO5: Voter ID | AQ5: 2 | AR5: Passport | AT5: 03 | AU5: PAN | AW5: 2 | AX5: Low Vision | AZ5: AP | BA5: ANDHRA PRADESH | BC5: AX | BD5: Aland Islands
A6: T | B6: Transgender | J6: 05 | K6: Minor | M6: 03 | N6: Foreign National | V6: 03 | W6: Data received from offline verification | AH6: B | AI6: Partnership Firm | AK6: 3 | AL6: Authorised Representative | AN6: C | AO6: PAN | AQ6: 3 | AR6: Driving License | AT6: 04 | AU6: Proof of Possession of Aadhaar | AW6: 3 | AX6: Hearing Impairment | AZ6: AR | BA6: ARUNACHAL PRADESH | BC6: AL | BD6: Albania
M7: 04 | N7: Person of Indian Origin | V7: 04 | W7: Digital KYC process | AH7: C | AI7: HUF | AK7: 4 | AL7: Director | AN7: D | AO7: Driving Licence | AQ7: 4 | AR7: Voters Identity Card | AT7: 05 | AU7: Passport | AW7: 4 | AX7: Locomotor Disability | AZ7: AS | BA7: ASSAM | BC7: DZ | BD7: Algeria
V8: 05 | W8: Equivalent e-document | AH8: D | AI8: Private Limited Company | AK8: 5 | AL8: Promoter | AN8: E | AO8: Proof of Possession of Aadhaar | AQ8: 5 | AR8: NREGA Job Card | AT8: 06 | AU8: Driving License | AW8: 5 | AX8: Leprosy Cured | AZ8: BR | BA8: BIHAR | BC8: AS | BD8: American Samoa
V9: 06 | W9: Video-based KYC | AH9: E | AI9: Public Limited Company | AK9: 6 | AL9: Karta | AN9: F | AO9: NREGA Job Card | AQ9: 6 | AR9: Certificate of Incorporation/Formation | AT9: 07 | AU9: Voters Identity Card | AW9: 6 | AX9: Cerebral Palsy | AZ9: CG | BA9: CHHATTISGARH | BC9: AD | BD9: Andorra
AH10: F | AI10: Society | AK10: 7 | AL10: Trustee | AN10: G | AO10: National Population Register Letter | AQ10: 7 | AR10: Registration Certificate | AT10: 08 | AU10: NREGA Job Card | AW10: 7 | AX10: Intellectual Disability | AZ10: CH | BA10: CHANDIGARH | BC10: AO | BD10: Angola
AH11: G | AI11: Association of Persons (AOP)/ Body of Individuals (BOI) | AK11: 8 | AL11: Partner | AN11: H | AO11: E-KYC Authentication | AQ11: 8 | AR11: National Population Register Letter | AT11: 09 | AU11: Signature | AW11: 8 | AX11: Mental Illness | AZ11: DD | BA11: THE DADRA AND NAGAR HAVELI AND DAMAN AND DIU | BC11: AI | BD11: Anguilla
AH12: H | AI12: Trust | AK12: 9 | AL12: Proprietor | AN12: I | AO12: Offline Verification of Aadhaar | AQ12: 9 | AR12: E-KYC Authentication | AT12: 10 | AU12: Simplified Measures Account - Identity card with applicant’s photograph issued by Central/ State Government Departments, Statutory/ Regulatory Authorities, Public Sector Undertakings, Scheduled Commercial Banks, and Public Financial Institutions. | AW12: 9 | AX12: Muscular Dystrophy | AZ12: DL | BA12: DELHI | BC12: AQ | BD12: Antarctica
AH13: I | AI13: Liquidator | AK13: 10 | AL13: Court Appointed Official | AN13: J | AO13: Documents issued by Government departments of foreign jurisdictions and letter issued by Foreign Embassy or Mission in India. API tag: <FOREIGN_NATIONAL_ID> | AQ13: 10 | AR13: Offline verification of Aadhaar | AT13: 11 | AU13: Simplified Measures Account - Letter issued by a gazetted officer, with a duly attested photograph of the person. | AW13: 10 | AX13: Parkinson's Disease | AZ13: DN | BA13: DADRA AND NAGAR HAVELI | BC13: AG | BD13: Antigua and Barbuda
AH14: J | AI14: Limited Liability Partnership | AK14: 11 | AL14: Beneficiary | AN14: Z | AO14: Others | AQ14: 11 | AR14: Utility bill which is not more than two months old of any service provider (electricity, telephone, post-paid mobile phone, piped gas, water bill). | AT14: 12 | AU14: Utility bill which is not more than two months old of any service provider (electricity, telephone, post-paid mobile phone, piped gas, water bill). | AW14: 11 | AX14: Acid Attack Victim | AZ14: GA | BA14: GOA | BC14: AR | BD14: Argentina
AH15: K | AI15: Artificial Liability Partnership | AK15: 12 | AL15: Authorised Signatory | AN15: S01 | AO15: Simplified Measures Account - Identity card with applicant’s photograph issued by Central/ State Government Departments, Statutory/ Regulatory Authorities, Public Sector Undertakings, Scheduled Commercial Banks, and Public Financial Institutions. | AQ15: 12 | AR15: Property or Municipal Tax receipt. | AT15: 13 | AU15: Property or Municipal Tax receipt. | AW15: 12 | AX15: Sickle Cell Disease | AZ15: GJ | BA15: GUJARAT | BC15: AM | BD15: Armenia
AH16: L | AI16: Public Sector Banks | AK16: 13 | AL16: Beneficial Owner | AN16: S02 | AO16: Simplified Measures Account - Letter issued by a gazetted officer, with a duly attested photograph of the person. | AQ16: 13 | AR16: Pension or family pension payment orders (PPOs) issued to retired employees by Government Departments or Public Sector Undertakings, if they contain the address. | AT16: 14 | AU16: Bank account or Post Office savings bank account statement. | AW16: 13 | AX16: Hemophilia | AZ16: HP | BA16: HIMACHAL PRADESH | BC16: AW | BD16: Aruba
AH17: M | AI17: Central/State Government Departments/Agency | AK17: 14 | AL17: Power of Attorney holder | AN17: 01 | AO17: Officially valid document(s) in respect of person authorized to transact | AQ17: 14 | AR17: Letter of allotment of accommodation from employer issued by State or Central Government departments, statutory or regulatory bodies, public sector undertakings, scheduled commercial banks, financial institutions and listed companies. Similarly, leave and license agreements with such employers allotting official accommodation. | AT17: 15 | AU17: Pension or family pension payment orders (PPOs) issued to retired employees by Government Departments or Public Sector Undertakings, if they contain the address. | AW17: 14 | AX17: Thalassemia | AZ17: HR | BA17: HARYANA | BC17: AU | BD17: Australia
AH18: N | AI18: Section 8 (Companies Act, 2013) | AK18: 15 | AL18: Other | AN18: 02 | AO18: Certificate of Incorporation/Formation | AQ18: 15 | AR18: Self Declaration | AT18: 16 | AU18: Letter of allotment of accommodation from employer issued by State or Central Government departments, statutory or regulatory bodies, public sector undertakings, scheduled commercial banks, financial institutions and listed companies. Similarly, leave and license agreements with such employers allotting official accommodation. | AW18: 15 | AX18: Speech and Language Disability | AZ18: JH | BA18: JHARKHAND | BC18: AT | BD18: Austria
AH19: O | AI19: Artificial Juridical Person | AN19: 03 | AO19: Registration Certificate | AQ19: 16 | AR19: Documents issued by the Government departments of foreign jurisdictions and letter issued by the Foreign Embassy or Mission in India API tag: <FOREIGN_NATIONAL_ID> | AT19: 17 | AU19: Documents issued by Government departments of foreign jurisdictions and letter issued by Foreign Embassy or Mission in India. | AW19: 16 | AX19: Multiple Sclerosis | AZ19: JK | BA19: JAMMU AND KASHMIR | BC19: AZ | BD19: Azerbaijan
AH20: P | AI20: International Organisation or Agency/Foreign embasssy or consular office etc. | AN20: 04 | AO20: Memorandum and Articles of Association | AQ20: 99 | AR20: Other | AT20: 35 | AU20: National Population Registry Letter | AW20: 17 | AX20: Specific Learning Disabilities | AZ20: KA | BA20: KARNATAKA | BC20: BS | BD20: Bahamas
AH21: Q | AI21: Not Categorized | AN21: 05 | AO21: Partnership Deed | AT21: 36 | AU21: E-KYC Authentication | AW21: 18 | AX21: Chronic Neurological Conditions | AZ21: KL | BA21: KERALA | BC21: BH | BD21: Bahrain
AH22: R | AI22: Others | AN22: 06 | AO22: Trust Deed | AT22: 37 | AU22: Offline verification of Aadhaar | AW22: 19 | AX22: Autism Spectrum Disorder | AZ22: LA | BA22: LADAKH | BC22: BD | BD22: Bangladesh
AH23: S | AI23: Foreign Portfolio Investors | AN23: 07 | AO23: Resolution of Board/ Managing Committee | AT23: 38 | AU23: Utility bill which is not more than two months old of any service provider (electricity, telephone, post-paid mobile phone, piped gas, water bill). | AW23: 20 | AX23: Dwarfism | AZ23: LD | BA23: LAKSHADWEEP | BC23: BB | BD23: Barbados
AN24: 08 | AO24: Power of Attorney granted to its manager, officers or employees to transact on its behalf | AT24: 42 | AU24: Documents issued by Government departments of foreign jurisdictions and letter issued by Foreign Embassy or Mission in India. API tag: <FOREIGN_NATIONAL_ID> | AZ24: MH | BA24: MAHARASHTRA | BC24: BY | BD24: Belarus
AN25: 09 | AO25: Activity Proof – 1 | AT25: 97 | AU25: Death certificate | AZ25: ML | BA25: MEGHALAYA | BC25: BE | BD25: Belgium
AN26: 10 | AO26: Activity Proof – 2 | AT26: 18 | AU26: Officially valid document(s) in respect of person authorized to transact | AZ26: MN | BA26: MANIPUR | BC26: BZ | BD26: Belize
AT27: 19 | AU27: Certificate of Incorporation/Formation | AZ27: MP | BA27: MADHYA PRADESH | BC27: BJ | BD27: Benin
AT28: 20 | AU28: Registration Certificate | AZ28: MZ | BA28: MIZORAM | BC28: BM | BD28: Bermuda
AT29: 21 | AU29: Memorandum and Articles of Association | AZ29: NL | BA29: NAGALAND | BC29: BT | BD29: Bhutan
AT30: 22 | AU30: Partnership Deed | AZ30: OD | BA30: ODISHA | BC30: BO | BD30: Bolivia, Plurinational State of
AT31: 23 | AU31: Trust Deed | AZ31: OR | BA31: ODISHA | BC31: BQ | BD31: Bonaire, Sint Eustatius and Saba
AT32: 24 | AU32: Resolution of Board/ Managing Committee | AZ32: PB | BA32: PUNJAB | BC32: BA | BD32: Bosnia and Herzegovina
AT33: 25 | AU33: Power of Attorney granted to its manager, officers or employees to transact on its behalf. | AZ33: PY | BA33: PUDUCHERRY | BC33: BW | BD33: Botswana
AT34: 26 | AU34: Activity Proof – 1 (For Sole Proprietorship only) | AZ34: RJ | BA34: RAJASTHAN | BC34: BV | BD34: Bouvet Island
AT35: 27 | AU35: Activity Proof – 2 (For Sole Proprietorship only) | AZ35: SK | BA35: SIKKIM | BC35: BR | BD35: Brazil
AT36: 98 | AU36: Other | AZ36: TG | BA36: TELANGANA | BC36: IO | BD36: British Indian Ocean Territory
AZ37: TN | BA37: TAMIL NADU | BC37: BN | BD37: Brunei Darussalam
AZ38: TR | BA38: TRIPURA | BC38: BG | BD38: Bulgaria
AZ39: TS | BA39: TELANGANA | BC39: BF | BD39: Burkina Faso
AZ40: UA | BA40: UTTARAKHAND | BC40: BI | BD40: Burundi
...
